2020-01-05 15:17:14,948 ERROR: Exception on /favicon.ico [GET] [in /home/solar/PycharmProjects/microblog_flask/venv/lib/python3.8/site-packages/flask/app.py:1890]
Traceback (most recent call last):
  File "/home/solar/PycharmProjects/microblog_flask/venv/lib/python3.8/site-packages/flask/app.py", line 1949, in full_dispatch_request
    rv = self.dispatch_request()
  File "/home/solar/PycharmProjects/microblog_flask/venv/lib/python3.8/site-packages/flask/app.py", line 1925, in dispatch_request
    self.raise_routing_exception(req)
  File "/home/solar/PycharmProjects/microblog_flask/venv/lib/python3.8/site-packages/flask/app.py", line 1907, in raise_routing_exception
    raise request.routing_exception
  File "/home/solar/PycharmProjects/microblog_flask/venv/lib/python3.8/site-packages/flask/ctx.py", line 350, in match_request
    result = self.url_adapter.match(return_rule=True)
  File "/home/solar/PycharmProjects/microblog_flask/venv/lib/python3.8/site-packages/werkzeug/routing.py", line 1799, in match
    raise NotFound()
werkzeug.exceptions.NotFound: 404 Not Found: The requested URL was not found on the server. If you entered the URL manually please check your spelling and try again.

During handling of the above exception, another exception occurred:

Traceback (most recent call last):
  File "/home/solar/PycharmProjects/microblog_flask/venv/lib/python3.8/site-packages/flask/app.py", line 2446, in wsgi_app
    response = self.full_dispatch_request()
  File "/home/solar/PycharmProjects/microblog_flask/venv/lib/python3.8/site-packages/flask/app.py", line 1951, in full_dispatch_request
    rv = self.handle_user_exception(e)
  File "/home/solar/PycharmProjects/microblog_flask/venv/lib/python3.8/site-packages/flask/app.py", line 1815, in handle_user_exception
    return self.handle_http_exception(e)
  File "/home/solar/PycharmProjects/microblog_flask/venv/lib/python3.8/site-packages/flask/app.py", line 1743, in handle_http_exception
    return handler(e)
  File "/home/solar/PycharmProjects/microblog_flask/app/errors/handlers.py", line 8, in not_found_error
    return render_template('errors/404.html'), 404
  File "/home/solar/PycharmProjects/microblog_flask/venv/lib/python3.8/site-packages/flask/templating.py", line 137, in render_template
    return _render(
  File "/home/solar/PycharmProjects/microblog_flask/venv/lib/python3.8/site-packages/flask/templating.py", line 120, in _render
    rv = template.render(context)
  File "/home/solar/PycharmProjects/microblog_flask/venv/lib/python3.8/site-packages/jinja2/asyncsupport.py", line 76, in render
    return original_render(self, *args, **kwargs)
  File "/home/solar/PycharmProjects/microblog_flask/venv/lib/python3.8/site-packages/jinja2/environment.py", line 1008, in render
    return self.environment.handle_exception(exc_info, True)
  File "/home/solar/PycharmProjects/microblog_flask/venv/lib/python3.8/site-packages/jinja2/environment.py", line 780, in handle_exception
    reraise(exc_type, exc_value, tb)
  File "/home/solar/PycharmProjects/microblog_flask/venv/lib/python3.8/site-packages/jinja2/_compat.py", line 37, in reraise
    raise value.with_traceback(tb)
  File "/home/solar/PycharmProjects/microblog_flask/app/templates/errors/404.html", line 1, in <module>
    {% extends "base.html" %}
  File "/home/solar/PycharmProjects/microblog_flask/venv/lib/python3.8/site-packages/jinja2/environment.py", line 1005, in render
    return concat(self.root_render_func(self.new_context(vars)))
  File "/home/solar/PycharmProjects/microblog_flask/app/templates/errors/404.html", line 14, in root
  File "/home/solar/PycharmProjects/microblog_flask/app/templates/base.html", line 14, in root
    <span class="icon-bar"></span>
  File "/home/solar/PycharmProjects/microblog_flask/venv/lib/python3.8/site-packages/flask_bootstrap/templates/bootstrap/base.html", line 10, in root
    <meta name="viewport" content="width=device-width, initial-scale=1.0">
  File "/home/solar/PycharmProjects/microblog_flask/venv/lib/python3.8/site-packages/flask_bootstrap/templates/bootstrap/base.html", line 20, in block_doc
    {% block body -%}
  File "/home/solar/PycharmProjects/microblog_flask/venv/lib/python3.8/site-packages/flask_bootstrap/templates/bootstrap/base.html", line 39, in block_html
  File "/home/solar/PycharmProjects/microblog_flask/venv/lib/python3.8/site-packages/flask_bootstrap/templates/bootstrap/base.html", line 90, in block_body
  File "/home/solar/PycharmProjects/microblog_flask/app/templates/base.html", line 59, in block_navbar
    $.post('/translate', {
  File "/home/solar/PycharmProjects/microblog_flask/venv/lib/python3.8/site-packages/jinja2/runtime.py", line 262, in call
    return __obj(*args, **kwargs)
  File "/home/solar/PycharmProjects/microblog_flask/venv/lib/python3.8/site-packages/flask/helpers.py", line 370, in url_for
    return appctx.app.handle_url_build_error(error, endpoint, values)
  File "/home/solar/PycharmProjects/microblog_flask/venv/lib/python3.8/site-packages/flask/app.py", line 2215, in handle_url_build_error
    reraise(exc_type, exc_value, tb)
  File "/home/solar/PycharmProjects/microblog_flask/venv/lib/python3.8/site-packages/flask/_compat.py", line 39, in reraise
    raise value
  File "/home/solar/PycharmProjects/microblog_flask/venv/lib/python3.8/site-packages/flask/helpers.py", line 357, in url_for
    rv = url_adapter.build(
  File "/home/solar/PycharmProjects/microblog_flask/venv/lib/python3.8/site-packages/werkzeug/routing.py", line 2020, in build
    raise BuildError(endpoint, values, method, self)
werkzeug.routing.BuildError: Could not build url for endpoint 'main.logout'. Did you mean 'auth.logout' instead?
2020-01-05 15:17:52,646 INFO: Microblog startup [in /home/solar/PycharmProjects/microblog_flask/app/__init__.py:74]
