2019-12-11 22:27:10,426 ERROR: Exception on /explore [GET] [in /home/solar/PycharmProjects/microblog_flask/venv/lib/python3.8/site-packages/flask/app.py:1890]
Traceback (most recent call last):
  File "/home/solar/PycharmProjects/microblog_flask/venv/lib/python3.8/site-packages/flask/app.py", line 2446, in wsgi_app
    response = self.full_dispatch_request()
  File "/home/solar/PycharmProjects/microblog_flask/venv/lib/python3.8/site-packages/flask/app.py", line 1951, in full_dispatch_request
    rv = self.handle_user_exception(e)
  File "/home/solar/PycharmProjects/microblog_flask/venv/lib/python3.8/site-packages/flask/app.py", line 1820, in handle_user_exception
    reraise(exc_type, exc_value, tb)
  File "/home/solar/PycharmProjects/microblog_flask/venv/lib/python3.8/site-packages/flask/_compat.py", line 39, in reraise
    raise value
  File "/home/solar/PycharmProjects/microblog_flask/venv/lib/python3.8/site-packages/flask/app.py", line 1949, in full_dispatch_request
    rv = self.dispatch_request()
  File "/home/solar/PycharmProjects/microblog_flask/venv/lib/python3.8/site-packages/flask/app.py", line 1935, in dispatch_request
    return self.view_functions[rule.endpoint](**req.view_args)
  File "/home/solar/PycharmProjects/microblog_flask/venv/lib/python3.8/site-packages/flask_login/utils.py", line 261, in decorated_view
    return func(*args, **kwargs)
  File "/home/solar/PycharmProjects/microblog_flask/app/routes.py", line 149, in explore
    'index.html', title='Explore', posts=posts.posts.items)
AttributeError: 'Pagination' object has no attribute 'posts'
2019-12-11 22:30:13,811 INFO: Microblog startup [in /home/solar/PycharmProjects/microblog_flask/app/__init__.py:45]
2019-12-11 23:03:09,326 INFO: Microblog startup [in /home/solar/PycharmProjects/microblog_flask/app/__init__.py:45]
2019-12-11 23:03:15,683 ERROR: Exception on /explore [GET] [in /home/solar/PycharmProjects/microblog_flask/venv/lib/python3.8/site-packages/flask/app.py:1890]
Traceback (most recent call last):
  File "/home/solar/PycharmProjects/microblog_flask/venv/lib/python3.8/site-packages/flask/app.py", line 2446, in wsgi_app
    response = self.full_dispatch_request()
  File "/home/solar/PycharmProjects/microblog_flask/venv/lib/python3.8/site-packages/flask/app.py", line 1951, in full_dispatch_request
    rv = self.handle_user_exception(e)
  File "/home/solar/PycharmProjects/microblog_flask/venv/lib/python3.8/site-packages/flask/app.py", line 1820, in handle_user_exception
    reraise(exc_type, exc_value, tb)
  File "/home/solar/PycharmProjects/microblog_flask/venv/lib/python3.8/site-packages/flask/_compat.py", line 39, in reraise
    raise value
  File "/home/solar/PycharmProjects/microblog_flask/venv/lib/python3.8/site-packages/flask/app.py", line 1949, in full_dispatch_request
    rv = self.dispatch_request()
  File "/home/solar/PycharmProjects/microblog_flask/venv/lib/python3.8/site-packages/flask/app.py", line 1935, in dispatch_request
    return self.view_functions[rule.endpoint](**req.view_args)
  File "/home/solar/PycharmProjects/microblog_flask/venv/lib/python3.8/site-packages/flask_login/utils.py", line 261, in decorated_view
    return func(*args, **kwargs)
  File "/home/solar/PycharmProjects/microblog_flask/app/routes.py", line 155, in explore
    prev_url = url_for('explore', page=page.prev_num) \
AttributeError: 'int' object has no attribute 'prev_num'
2019-12-11 23:10:17,897 INFO: Microblog startup [in /home/solar/PycharmProjects/microblog_flask/app/__init__.py:45]
